<?xml version="1.0"?>
<robot xmlns:xacro="http://www.ros.org/wiki/xacro" name="car_description">
    <!-- Define robot constants -->
    <xacro:property name="base_width" value="0.20"/>
    <xacro:property name="base_length" value="0.28"/>
    <xacro:property name="base_height" value="0.21"/>
    
    <xacro:property name="wheel_radius" value="0.035"/>
    <xacro:property name="wheel_width" value="0.025"/>
    <xacro:property name="wheel_ygap" value="0.01"/>
    <xacro:property name="wheel_zoff" value="0.035"/>
    <xacro:property name="wheel_xoff" value="0.09"/>
    
    <!-- Robot base -->
    <link name="base_link">
        <visual>
            <geometry>
                <box size="${base_length} ${base_width} ${base_height}"/>
            </geometry>
            <material name="Cyan">
                <color rgba="0 1 1 1"/>
            </material>
        </visual>
    </link>

    <!-- Robot Footprint -->
    <link name="base_footprint"/>

    <joint name="base_joint" type="fixed">
        <parent link="base_link"/>
        <child link="base_footprint"/>
        <origin xyz="0 0 ${-(wheel_radius+wheel_zoff)}" rpy="0 0 0"/>
        <!--axis xyz="0 0 0"/-->
    </joint>

    <!-- Wheels -->
    <xacro:macro name="wheel" params="prefix x_reflect y_reflect">
        <link name="${prefix}_link">
            <visual>
                <geometry>
                    <cylinder radius="${wheel_radius}" length="${wheel_width}"/>
                </geometry>
                <material name="Gray">
                    <color rgba="0.5 0.5 0.5 1"/>
                </material>
            </visual>
        </link>

        <joint name="${prefix}_joint" type="continuous">
            <parent link="base_link"/>
            <child link="${prefix}_link"/>
            <origin xyz="${x_reflect*wheel_xoff} ${y_reflect*(base_width/2+wheel_ygap)} ${-wheel_zoff}" rpy="0 0 0"/>
            <axis xyz="0 1 0"/>
        </joint>
        </link>
    </xacro:macro>

    <xacro:wheel prefix="left_front" x_reflect="1" y_reflect="1"/>
    <xacro:wheel prefix="right_front" x_reflect="1" y_reflect="-1"/>
    <xacro:wheel prefix="left_rear" x_reflect="-1" y_reflect="1"/>
    <xacro:wheel prefix="right_rear" x_reflect="-1" y_reflect="-1"/>
</robot>
